Workbook

Sheet TF_std
A1: 업체명 (Eng) | B1: 국가/지역 | C1: 행정구역 | D1: 주소 | E1: STD 업체명 | F1: STD 주소 | G1: 표준화 | H1: 분류 코드 | I1: 비고 | J1: 표준 위도 | K1: 표준 경도 | L1: place_id | M1: 참조 URL | N1: Note | O1: addressComponents | Q1: 소계 | R1: =ROWS(G2:G25) -> 24
A2: Suzhou Kematek, Inc. | B2: CN:중국 | C2: 100:Jiangsu | D2: 1 San Qian Road Suzhou Gaoxin District | E2: Suzhou Kematek | F2: China, Su Zhou Shi, Hu Qiu Qu, CN 江苏省 苏州市 虎丘区 漓江路 58 58号苏州科技城工业坊B区6栋 邮政编码: 215163 | G2: 검증 완료 | H2: VERIFIED_GEOCODE_DIRECT | I2: 지오코딩 성공, 표준좌표 기준 TextSearch 매칭(G 도시레벨→TS 좌표 채택) | J2: 31.362200 | K2: 120.415390 | L2: ChIJmegxpsmdszURxrpKRCsOcA8 | M2: https://www.google.com/maps/place/?q=place_id:ChIJmegxpsmdszURxrpKRCsOcA8 | O2: [{"types": [], "long_text": "CN 江苏省 苏州市 虎丘区 漓江路 58 58号苏州科技城工业坊B区6栋", "short_text": "", "language_code": "zh", "source_api": "places_new"}, {"types": ["country", "political"], "long_text": "China", "short_text": "CN", "language_code": "en", "source_api": "places_new"}, {"types": ["sublocality_level_1", "sublocality", "political"], "long_text": "Hu Qiu Qu", "short_text": "Hu Qiu Qu", "language_code": "zh-Latn", "source_api": "places_new"}, {"types": ["locality", "political"], "long_text": "Su Zhou Shi", "short_text": "Su Zhou Shi", "language_code": "zh-Latn", "source_api": "places_new"}, {"types": ["postal_code"], "long_text": "215163", "short_text": "215163", "language_code": "en-US", "source_api": "places_new"}] | Q2: 검증 완료 | R2: =COUNTIF(G2:G25, "검증 완료") -> 11
A3: Honeywell Automation and Control Solution(China) Co.,Ltd. | B3: CN:중국 | C3: 020:Shanghai | D3: FUTE NORTH ROAD NO.456 5F A2 ROOM SHANGHAI PILOT FREE TRADE ZONE | E3: Honeywell Automation and Control Solution(China) | F3: Shanghai, China | G3: 확인 필요 | H3: UNVERIFIED_NOT_FOUND | I3: 지오코딩은 성공했으나 TextSearch(좌표·주소텍스트)에서 업체 미발견 | J3: 31.230416 | K3: 121.473701 | M3: https://www.google.com/maps/search/?api=1&query=Honeywell%20Automation%20and%20Control%20Solution%28China%29%20Co.%2CLtd.%20FUTE%20NORTH%20ROAD%20NO.456%205F%20A2%20ROOM%20SHANGHAI%20PILOT%20FREE%20TRADE%20ZONE | O3: [{"types": ["locality", "political"], "long_text": "Shanghai", "short_text": "Shanghai", "language_code": null, "source_api": "geocoding"}, {"types": ["administrative_area_level_1", "political"], "long_text": "Shanghai", "short_text": "Shanghai", "language_code": null, "source_api": "geocoding"}, {"types": ["country", "political"], "long_text": "China", "short_text": "CN", "language_code": null, "source_api": "geocoding"}] | Q3: 확인 필요 | R3: =COUNTIF(G2:G25, "확인 필요") -> 12
A4: CINOS(CX1,CX2) | B4: CN:중국 | C4: 250:Shaanxi | D4: 중국 Shan Xi Sheng, Xi An Shi, Ba Qiao Qu, 亚洲道93WF+8X9 邮政编码: 710027 | E4: CINOS(CX1,CX2) | F4: China, Shan Xi Sheng, Xi An Shi, Ba Qiao Qu, 亚洲道93WG+FFR 邮政编码: 710027 | G4: 확인 필요 | H4: UNVERIFIED_NOT_FOUND | I4: 지오코딩은 성공했으나 TextSearch(좌표·주소텍스트)에서 업체 미발견 | J4: 34.396238 | K4: 109.076148 | M4: https://www.google.com/maps/search/?api=1&query=CINOS%28CX1%2CCX2%29%20%EC%A4%91%EA%B5%AD%20Shan%20Xi%20Sheng%2C%20Xi%20An%20Shi%2C%20Ba%20Qiao%20Qu%2C%20%E4%BA%9A%E6%B4%B2%E9%81%9393WF%2B8X9%20%E9%82%AE%E6%94%BF%E7%BC%96%E7%A0%81%3A%20710027 | O4: [{"types": ["plus_code"], "long_text": "93WG+FFR", "short_text": "93WG+FFR", "language_code": null, "source_api": "geocoding"}, {"types": ["route"], "long_text": "亚洲道", "short_text": "亚洲道", "language_code": null, "source_api": "geocoding"}, {"types": ["political", "sublocality", "sublocality_level_1"], "long_text": "Ba Qiao Qu", "short_text": "Ba Qiao Qu", "language_code": null, "source_api": "geocoding"}, {"types": ["locality", "political"], "long_text": "Xi An Shi", "short_text": "Xi An Shi", "language_code": null, "source_api": "geocoding"}, {"types": ["administrative_area_level_1", "political"], "long_text": "Shan Xi Sheng", "short_text": "Shan Xi Sheng", "language_code": null, "source_api": "geocoding"}, {"types": ["country", "political"], "long_text": "China", "short_text": "CN", "language_code": null, "source_api": "geocoding"}, {"types": ["postal_code"], "long_text": "710027", "short_text": "710027", "language_code": null, "source_api": "geocoding"}] | Q4: 실패 | R4: =COUNTIF(G2:G25, "실패") -> 1
A5: Air Liquide Electronics US LP | B5: US:미합중국 | C5: US_99 | D5: PO BOX 200269 HOUSTON TX | E5: Air Liquide Electronics US LP | F5: 9811 Katy Fwy #100, Houston, TX 77024, USA | G5: 검증 완료 | H5: VERIFIED_GEOCODE_DIRECT | I5: 지오코딩 성공, 표준좌표 기준 TextSearch 매칭(G 도시레벨→TS 좌표 채택) | J5: 29.782451 | K5: -95.536400 | L5: ChIJsTtJC6y4QIYRSI2XSZdeW3Q | M5: https://www.google.com/maps/place/?q=place_id:ChIJsTtJC6y4QIYRSI2XSZdeW3Q | O5: [{"types": ["subpremise"], "long_text": "100", "short_text": "100", "language_code": "en", "source_api": "places_new"}, {"types": ["street_number"], "long_text": "9811", "short_text": "9811", "language_code": "en-US", "source_api": "places_new"}, {"types": ["route"], "long_text": "Katy Freeway", "short_text": "Katy Fwy", "language_code": "en", "source_api": "places_new"}, {"types": ["neighborhood", "political"], "long_text": "Memorial City", "short_text": "Memorial City", "language_code": "en", "source_api": "places_new"}, {"types": ["locality", "political"], "long_text": "Houston", "short_text": "Houston", "language_code": "en", "source_api": "places_new"}, {"types": ["administrative_area_level_2", "political"], "long_text": "Harris County", "short_text": "Harris County", "language_code": "en", "source_api": "places_new"}, {"types": ["administrative_area_level_1", "political"], "long_text": "Texas", "short_text": "TX", "language_code": "en", "source_api": "places_new"}, {"types": ["country", "political"], "long_text": "United States", "short_text": "US", "language_code": "en", "source_api": "places_new"}, {"types": ["postal_code"], "long_text": "77024", "short_text": "77024", "language_code": "en-US", "source_api": "places_new"}]
A6: CINOS(C4) | B6: KR:한국 | C6: 09:Gyeonggi-do | D6: 대한민국 경기도 화성시 향남읍 구문천리 929-2 | E6: CINOS(C4) | F6: 929-2 Gumuncheon-ri, Hyangnam-eup, Hwaseong-si, Gyeonggi-do, South Korea | G6: 검증 완료 | H6: VERIFIED_GEOCODE_PROXIMITY | I6: 지오코딩 성공, 표준좌표 기준 TextSearch 매칭(정밀좌표 근접 POI 수용: 업체명 표기 상이) | J6: 37.085472 | K6: 126.900052 | L6: ChIJ83c4KwAXezURJ2oNR5ylGaY | M6: https://www.google.com/maps/place/?q=place_id:ChIJ83c4KwAXezURJ2oNR5ylGaY | O6: [{"types": ["sublocality_level_3", "sublocality", "political"], "long_text": "Gumuncheon-ri", "short_text": "Gumuncheon-ri", "language_code": "en", "source_api": "places_new"}, {"types": ["sublocality_level_2", "sublocality", "political"], "long_text": "Hyangnam-eup", "short_text": "Hyangnam-eup", "language_code": "en", "source_api": "places_new"}, {"types": ["locality", "political"], "long_text": "Hwaseong-si", "short_text": "Hwaseong-si", "language_code": "en", "source_api": "places_new"}, {"types": ["country", "political"], "long_text": "South Korea", "short_text": "KR", "language_code": "en", "source_api": "places_new"}, {"types": ["postal_code"], "long_text": "18623", "short_text": "18623", "language_code": "en-US", "source_api": "places_new"}]
A7: CINOS(C1) | B7: KR:한국 | C7: 09:Gyeonggi-do | D7: 대한민국 경기도 화성시 팔탄면 가재리 299-2 | E7: CINOS(C1) | F7: 299-2 Gajae-ri, Paltan-myeon, Hwaseong-si, Gyeonggi-do, South Korea | G7: 확인 필요 | H7: UNVERIFIED_NOT_FOUND | I7: 지오코딩은 성공했으나 TextSearch(좌표·주소텍스트)에서 업체 미발견 | J7: 37.157271 | K7: 126.926767 | M7: https://www.google.com/maps/search/?api=1&query=CINOS%28C1%29%20%EB%8C%80%ED%95%9C%EB%AF%BC%EA%B5%AD%20%EA%B2%BD%EA%B8%B0%EB%8F%84%20%ED%99%94%EC%84%B1%EC%8B%9C%20%ED%8C%94%ED%83%84%EB%A9%B4%20%EA%B0%80%EC%9E%AC%EB%A6%AC%20299-2 | O7: [{"types": ["premise"], "long_text": "299-2", "short_text": "299-2", "language_code": null, "source_api": "geocoding"}, {"types": ["political", "sublocality", "sublocality_level_3"], "long_text": "Gajae-ri", "short_text": "Gajae-ri", "language_code": null, "source_api": "geocoding"}, {"types": ["political", "sublocality", "sublocality_level_2"], "long_text": "Paltan-myeon", "short_text": "Paltan-myeon", "language_code": null, "source_api": "geocoding"}, {"types": ["locality", "political"], "long_text": "Hwaseong-si", "short_text": "Hwaseong-si", "language_code": null, "source_api": "geocoding"}, {"types": ["administrative_area_level_1", "political"], "long_text": "Gyeonggi-do", "short_text": "Gyeonggi-do", "language_code": null, "source_api": "geocoding"}, {"types": ["country", "political"], "long_text": "South Korea", "short_text": "KR", "language_code": null, "source_api": "geocoding"}, {"types": ["postal_code"], "long_text": "18533", "short_text": "18533", "language_code": null, "source_api": "geocoding"}]
A8: Solstice Electronic Materials - Spokane | B8: US:미합중국 | C8: US_WA | D8: PO BOX 100257 PASADENA CA | E8: Solstice Electronic Materials - Spokane | F8: Pasadena, CA, USA | G8: 확인 필요 | H8: UNVERIFIED_NOT_FOUND | I8: 지오코딩은 성공했으나 TextSearch(좌표·주소텍스트)에서 업체 미발견 | J8: 34.147653 | K8: -118.144302 | M8: https://www.google.com/maps/search/?api=1&query=Solstice%20Electronic%20Materials%20-%20Spokane%20PO%20BOX%20100257%20PASADENA%20CA | O8: [{"types": ["locality", "political"], "long_text": "Pasadena", "short_text": "Pasadena", "language_code": null, "source_api": "geocoding"}, {"types": ["administrative_area_level_2", "political"], "long_text": "Los Angeles County", "short_text": "Los Angeles County", "language_code": null, "source_api": "geocoding"}, {"types": ["administrative_area_level_1", "political"], "long_text": "California", "short_text": "CA", "language_code": null, "source_api": "geocoding"}, {"types": ["country", "political"], "long_text": "United States", "short_text": "US", "language_code": null, "source_api": "geocoding"}]
A9: CW QUERETARO MEXICO SA DE CV | B9: MX:멕시코 | C9: MX_QRO | D9: RHH5+52, El Puerto, Querétaro, Mexico, 76215 | E9: CW QUERETARO MEXICO SA DE CV | F9: RHH5+52 Querétaro, Mexico | G9: 확인 필요 | H9: UNVERIFIED_NOT_FOUND | I9: 지오코딩은 성공했으나 TextSearch(좌표·주소텍스트)에서 업체 미발견 | J9: 20.827938 | K9: -100.442437 | M9: https://www.google.com/maps/search/?api=1&query=CW%20QUERETARO%20MEXICO%20SA%20DE%20CV%20RHH5%2B52%2C%20El%20Puerto%2C%20Quer%C3%A9taro%2C%20Mexico%2C%2076215 | O9: [{"types": ["plus_code"], "long_text": "RHH5+52", "short_text": "RHH5+52", "language_code": null, "source_api": "geocoding"}, {"types": ["administrative_area_level_1", "political"], "long_text": "Querétaro", "short_text": "Qro.", "language_code": null, "source_api": "geocoding"}, {"types": ["country", "political"], "long_text": "Mexico", "short_text": "MX", "language_code": null, "source_api": "geocoding"}, {"types": ["postal_code"], "long_text": "76215", "short_text": "76215", "language_code": null, "source_api": "geocoding"}]
A10: Entegris Malaysia Sdn Bhd | B10: MY:말레이시아 | C10: KED:Kedah | D10: Perdana Highway, Kampung Sungai Seluang, Lunas, Kedah, Malaysia, 09600 | E10: Entegris Malaysia Sdn Bhd | F10: Lot 17, Fasa 1 Kulim Hi-Tech Park, Kedah, Taman Kulim Hi-tech, 09000 Kulim, Kedah, Malaysia | G10: 검증 완료 | H10: VERIFIED_TEXTSEARCH_ADDR_TEXT | I10: 표준좌표 TextSearch 미매칭, 업체명+주소텍스트 TextSearch로 매칭(레벨 L1) | L10: ChIJq6qqqubMSjAR7P43RFFhmpU | M10: https://www.google.com/maps/place/?q=place_id:ChIJq6qqqubMSjAR7P43RFFhmpU | O10: [{"types": [], "long_text": "Lot 17, Fasa 1 Kulim Hi-Tech Park, Kedah", "short_text": "", "language_code": "en", "source_api": "places_new"}, {"types": ["sublocality_level_1", "sublocality", "political"], "long_text": "Taman Kulim Hi-tech", "short_text": "Taman Kulim Hi-tech", "language_code": "en", "source_api": "places_new"}, {"types": ["locality", "political"], "long_text": "Kulim", "short_text": "Kulim", "language_code": "en", "source_api": "places_new"}, {"types": ["administrative_area_level_1", "political"], "long_text": "Kedah", "short_text": "Kedah", "language_code": "en", "source_api": "places_new"}, {"types": ["country", "political"], "long_text": "Malaysia", "short_text": "MY", "language_code": "en", "source_api": "places_new"}, {"types": ["postal_code"], "long_text": "09000", "short_text": "09000", "language_code": "en-US", "source_api": "places_new"}]
A11: SUZHOU NOBORT ELECTRONICS EQUIPMENT LIMITED COMPANY | B11: CN:중국 | C11: 99:China (General) | D11: 8Q9C+R6W, Xinghua Street, Wu Zhong Qu, Su Zhou Shi, Jiang Su Sheng, China, 215121 | E11: SUZHOU NOBORT ELECTRONICS EQUIPMENT LIMITED COMPANY | F11: 34 Jin Hai Lu, Wu Zhong Qu, Su Zhou Shi, Jiang Su Sheng, China, 215000 | G11: 검증 완료 | H11: VERIFIED_TEXTSEARCH_ADDR_TEXT | I11: 표준좌표 TextSearch 미매칭, 업체명+주소텍스트 TextSearch로 매칭(레벨 L3) | L11: ChIJ99jhXa2pszURVhN82bFMSDI | M11: https://www.google.com/maps/place/?q=place_id:ChIJ99jhXa2pszURVhN82bFMSDI | O11: [{"types": ["street_number"], "long_text": "34", "short_text": "34", "language_code": "en-US", "source_api": "places_new"}, {"types": ["route"], "long_text": "Jin Hai Lu", "short_text": "Jin Hai Lu", "language_code": "zh-Latn", "source_api": "places_new"}, {"types": ["sublocality_level_1", "sublocality", "political"], "long_text": "Wu Zhong Qu", "short_text": "Wu Zhong Qu", "language_code": "zh-Latn", "source_api": "places_new"}, {"types": ["locality", "political"], "long_text": "Su Zhou Shi", "short_text": "Su Zhou Shi", "language_code": "zh-Latn", "source_api": "places_new"}, {"types": ["administrative_area_level_1", "political"], "long_text": "Jiang Su Sheng", "short_text": "Jiang Su Sheng", "language_code": "zh-Latn", "source_api": "places_new"}, {"types": ["country", "political"], "long_text": "China", "short_text": "CN", "language_code": "en", "source_api": "places_new"}, {"types": ["postal_code"], "long_text": "215000", "short_text": "215000", "language_code": "en-US", "source_api": "places_new"}]
A12: CINOS(C2) | B12: KR:한국 | C12: 09:Gyeonggi-do | D12: 대한민국 경기도 화성시 향남읍 구문천리 930-17 | E12: CINOS(C2) | F12: 930-17 Gumuncheon-ri, Hyangnam-eup, Hwaseong-si, Gyeonggi-do, South Korea | G12: 확인 필요 | H12: UNVERIFIED_NOT_FOUND | I12: 지오코딩은 성공했으나 TextSearch(좌표·주소텍스트)에서 업체 미발견 | J12: 37.085127 | K12: 126.896852 | M12: https://www.google.com/maps/search/?api=1&query=CINOS%28C2%29%20%EB%8C%80%ED%95%9C%EB%AF%BC%EA%B5%AD%20%EA%B2%BD%EA%B8%B0%EB%8F%84%20%ED%99%94%EC%84%B1%EC%8B%9C%20%ED%96%A5%EB%82%A8%EC%9D%8D%20%EA%B5%AC%EB%AC%B8%EC%B2%9C%EB%A6%AC%20930-17 | O12: [{"types": ["premise"], "long_text": "930-17", "short_text": "930-17", "language_code": null, "source_api": "geocoding"}, {"types": ["political", "sublocality", "sublocality_level_3"], "long_text": "Gumuncheon-ri", "short_text": "Gumuncheon-ri", "language_code": null, "source_api": "geocoding"}, {"types": ["political", "sublocality", "sublocality_level_2"], "long_text": "Hyangnam-eup", "short_text": "Hyangnam-eup", "language_code": null, "source_api": "geocoding"}, {"types": ["locality", "political"], "long_text": "Hwaseong-si", "short_text": "Hwaseong-si", "language_code": null, "source_api": "geocoding"}, {"types": ["administrative_area_level_1", "political"], "long_text": "Gyeonggi-do", "short_text": "Gyeonggi-do", "language_code": null, "source_api": "geocoding"}, {"types": ["country", "political"], "long_text": "South Korea", "short_text": "KR", "language_code": null, "source_api": "geocoding"}, {"types": ["postal_code"], "long_text": "18623", "short_text": "18623", "language_code": null, "source_api": "geocoding"}]
A13: SJI SAIGON | B13: VN:베트남 | C13: 02:HCM City | D13: 35, Đường Đồng Khởi, thành phố Biên Hòa, Đồng Nai, Vietnam | E13: SJI SAIGON | F13: 35 Đ. Đồng Khởi, Tân Triều, Đồng Nai, Vietnam | G13: 확인 필요 | H13: UNVERIFIED_NOT_FOUND | I13: 지오코딩은 성공했으나 TextSearch(좌표·주소텍스트)에서 업체 미발견 | J13: 10.971882 | K13: 106.852692 | M13: https://www.google.com/maps/search/?api=1&query=SJI%20SAIGON%2035%2C%20%C4%90%C6%B0%E1%BB%9Dng%20%C4%90%E1%BB%93ng%20Kh%E1%BB%9Fi%2C%20th%C3%A0nh%20ph%E1%BB%91%20Bi%C3%AAn%20H%C3%B2a%2C%20%C4%90%E1%BB%93ng%20Nai%2C%20Vietnam | N13: 기존 주소 기반 URL | O13: [{"types": ["street_number"], "long_text": "35", "short_text": "35", "language_code": null, "source_api": "geocoding"}, {"types": ["route"], "long_text": "Đường Đồng Khởi", "short_text": "Đ. Đồng Khởi", "language_code": null, "source_api": "geocoding"}, {"types": ["locality", "political"], "long_text": "Đồng Nai", "short_text": "Đồng Nai", "language_code": null, "source_api": "geocoding"}, {"types": ["administrative_area_level_1", "political"], "long_text": "Đồng Nai", "short_text": "Đồng Nai", "language_code": null, "source_api": "geocoding"}, {"types": ["country", "political"], "long_text": "Vietnam", "short_text": "VN", "language_code": null, "source_api": "geocoding"}] | P13: 기존 URL이 더 정확
A14: SJI SAIGON | B14: VN:베트남 | C14: 02:HCM City | D14: 35 Đ. Đồng Khởi, Tân Hiệp, Biên Hòa, Đồng Nai 810000 베트남 | E14: SJI SAIGON | F14: XR4R+PHW, Tran Bien, Dong Nai City, Vietnam | G14: 확인 필요 | H14: UNVERIFIED_NOT_FOUND | I14: 지오코딩은 성공했으나 TextSearch(좌표·주소텍스트)에서 업체 미발견 | J14: 10.956862 | K14: 106.841441 | M14: https://www.google.com/maps/search/?api=1&query=SJI%20SAIGON%2035%20%C4%90.%20%C4%90%E1%BB%93ng%20Kh%E1%BB%9Fi%2C%20T%C3%A2n%20Hi%E1%BB%87p%2C%20Bi%C3%AAn%20H%C3%B2a%2C%20%C4%90%E1%BB%93ng%20Nai%20810000%20%EB%B2%A0%ED%8A%B8%EB%82%A8 | N14: 표준 주소 기반 URL | O14: [{"types": ["plus_code"], "long_text": "XR4R+PHW", "short_text": "XR4R+PHW", "language_code": null, "source_api": "geocoding"}, {"types": ["locality", "political"], "long_text": "Dong Nai City", "short_text": "Dong Nai City", "language_code": null, "source_api": "geocoding"}, {"types": ["administrative_area_level_1", "political"], "long_text": "Dong Nai City", "short_text": "Dong Nai City", "language_code": null, "source_api": "geocoding"}, {"types": ["country", "political"], "long_text": "Vietnam", "short_text": "VN", "language_code": null, "source_api": "geocoding"}] | P14: 표준 주소 URL이 더 정확 (기존 주소에 "베트남" 노이즈 존재하기 때문)
A15: SEGYUNG VINA CO.,LTD | B15: VN:베트남 | C15: 06:Bac Ninh | D15: Yên Phong, Bắc Ninh, Vietnam | E15: SEGYUNG VINA | F15: Unnamed, Road, Yên Trung, Bắc Ninh, Vietnam | G15: 검증 완료 | H15: VERIFIED_GEOCODE_DIRECT | I15: 지오코딩 성공, 표준좌표 기준 TextSearch 매칭(G 도시레벨→TS 좌표 채택) | J15: 21.227118 | K15: 105.996776 | L15: ChIJyZyNn1YPNTERIb6KZczsFVE | M15: https://www.google.com/maps/place/?q=place_id:ChIJyZyNn1YPNTERIb6KZczsFVE | O15: [{"types": ["route"], "long_text": "Unnamed", "short_text": "Unnamed", "language_code": "vi", "source_api": "places_new"}, {"types": ["neighborhood", "political"], "long_text": "Road", "short_text": "Road", "language_code": "vi", "source_api": "places_new"}, {"types": ["locality", "political"], "long_text": "Yên Trung", "short_text": "Yên Trung", "language_code": "vi", "source_api": "places_new"}, {"types": ["administrative_area_level_1", "political"], "long_text": "Bắc Ninh", "short_text": "Bắc Ninh", "language_code": "vi", "source_api": "places_new"}, {"types": ["country", "political"], "long_text": "Vietnam", "short_text": "VN", "language_code": "en", "source_api": "places_new"}]
A16: SI FLEX VIETNAM CO.,LTD. | B16: VN:베트남 | C16: 01:Hanoi | D16: Đường 1A, tt. Nếnh, Việt Yên, Bắc Giang, Vietnam | E16: SI FLEX VIETNAM | F16: Land lot A industrial zone, Nếnh, Bắc Ninh, Vietnam | G16: 검증 완료 | H16: VERIFIED_TEXTSEARCH_ADDR_TEXT | I16: 표준좌표 TextSearch 미매칭, 업체명+주소텍스트 TextSearch로 매칭(레벨 L1) | L16: ChIJLdXaZtoNNTERiTzFefw_X7o | M16: https://www.google.com/maps/place/?q=place_id:ChIJLdXaZtoNNTERiTzFefw_X7o | O16: [{"types": [], "long_text": "Land lot A industrial zone", "short_text": "", "language_code": "vi", "source_api": "places_new"}, {"types": ["locality", "political"], "long_text": "Nếnh", "short_text": "Nếnh", "language_code": "vi", "source_api": "places_new"}, {"types": ["administrative_area_level_1", "political"], "long_text": "Bắc Ninh", "short_text": "Bắc Ninh", "language_code": "vi", "source_api": "places_new"}, {"types": ["country", "political"], "long_text": "Vietnam", "short_text": "VN", "language_code": "en", "source_api": "places_new"}]
A17: 天水华天科技股份有限公司 | B17: CN:중국 | C17: 260:Gansu | D17: 秦州区天水郡街道秦州大道360号 天水 741001 CN | E17: 天水华天科技 | F17: Qin Zhou Da Dao, Qin Zhou Qu, Tian Shui Shi, Gan Su Sheng, China | G17: 확인 필요 | H17: UNVERIFIED_NOT_FOUND | I17: 지오코딩은 성공했으나 TextSearch(좌표·주소텍스트)에서 업체 미발견 | J17: 34.563560 | K17: 105.593670 | M17: https://www.google.com/maps/search/?api=1&query=%E5%A4%A9%E6%B0%B4%E5%8D%8E%E5%A4%A9%E7%A7%91%E6%8A%80%E8%82%A1%E4%BB%BD%E6%9C%89%E9%99%90%E5%85%AC%E5%8F%B8%20%E7%A7%A6%E5%B7%9E%E5%8C%BA%E5%A4%A9%E6%B0%B4%E9%83%A1%E8%A1%97%E9%81%93%E7%A7%A6%E5%B7%9E%E5%A4%A7%E9%81%93360%E5%8F%B7%20%20%E5%A4%A9%E6%B0%B4%20%20741001%20CN | O17: [{"types": ["route"], "long_text": "Qin Zhou Da Dao", "short_text": "Qin Zhou Da Dao", "language_code": null, "source_api": "geocoding"}, {"types": ["political", "sublocality", "sublocality_level_1"], "long_text": "Qin Zhou Qu", "short_text": "Qin Zhou Qu", "language_code": null, "source_api": "geocoding"}, {"types": ["locality", "political"], "long_text": "Tian Shui Shi", "short_text": "Tian Shui Shi", "language_code": null, "source_api": "geocoding"}, {"types": ["administrative_area_level_1", "political"], "long_text": "Gan Su Sheng", "short_text": "Gan Su Sheng", "language_code": null, "source_api": "geocoding"}, {"types": ["country", "political"], "long_text": "China", "short_text": "CN", "language_code": null, "source_api": "geocoding"}]
A18: 苏州新特式半导体有限公司 | B18: CN:중국 | C18: 100:Jiangsu | D18: 工业园区唯亭镇春辉路2号 苏州 215122 CN | E18: 苏州新特式半导体 | F18: 亭 镇, 2 Chun Hui Lu, Wu Zhong Qu, Su Zhou Shi, Jiang Su Sheng, China, 215121 | G18: 확인 필요 | H18: UNVERIFIED_NOT_FOUND | I18: 지오코딩은 성공했으나 TextSearch(좌표·주소텍스트)에서 업체 미발견 | J18: 31.353000 | K18: 120.749550 | M18: https://www.google.com/maps/search/?api=1&query=%E8%8B%8F%E5%B7%9E%E6%96%B0%E7%89%B9%E5%BC%8F%E5%8D%8A%E5%AF%BC%E4%BD%93%E6%9C%89%E9%99%90%E5%85%AC%E5%8F%B8%20%E5%B7%A5%E4%B8%9A%E5%9B%AD%E5%8C%BA%E5%94%AF%E4%BA%AD%E9%95%87%E6%98%A5%E8%BE%89%E8%B7%AF2%E5%8F%B7%20%20%E8%8B%8F%E5%B7%9E%20%20215122%20CN | N18: 기존 주소 기반 URL | O18: [{"types": ["subpremise"], "long_text": "亭 镇", "short_text": "亭 镇", "language_code": null, "source_api": "geocoding"}, {"types": ["street_number"], "long_text": "2", "short_text": "2", "language_code": null, "source_api": "geocoding"}, {"types": ["route"], "long_text": "Chun Hui Lu", "short_text": "Chun Hui Lu", "language_code": null, "source_api": "geocoding"}, {"types": ["political", "sublocality", "sublocality_level_1"], "long_text": "Wu Zhong Qu", "short_text": "Wu Zhong Qu", "language_code": null, "source_api": "geocoding"}, {"types": ["locality", "political"], "long_text": "Su Zhou Shi", "short_text": "Su Zhou Shi", "language_code": null, "source_api": "geocoding"}, {"types": ["administrative_area_level_1", "political"], "long_text": "Jiang Su Sheng", "short_text": "Jiang Su Sheng", "language_code": null, "source_api": "geocoding"}, {"types": ["country", "political"], "long_text": "China", "short_text": "CN", "language_code": null, "source_api": "geocoding"}, {"types": ["postal_code"], "long_text": "215121", "short_text": "215121", "language_code": null, "source_api": "geocoding"}] | P18: 기존 URL이 더 정확
A19: BOYD KOREA LLC | B19: KR:한국 | C19: 04:Chungcheongbuk-do | D19: (Hwagye-dong)2, 2Sunhwan-ro 742beon-gil, Heungdeok-gu, Cheongju-si, Chungcheongbuk-do | E19: BOYD KOREA | F19: 2 2sunhwan-ro 742beon-gil, Heungdeok-gu, Cheongju, Chungcheongbuk-do, South Korea | G19: 검증 완료 | H19: VERIFIED_GEOCODE_DIRECT | I19: 지오코딩 성공, 표준좌표 기준 TextSearch 매칭 | J19: 36.656145 | K19: 127.443492 | L19: ChIJFWasIsgpZTURvxEVwC2zlWk | M19: https://www.google.com/maps/place/?q=place_id:ChIJFWasIsgpZTURvxEVwC2zlWk | O19: [{"types": ["premise"], "long_text": "2", "short_text": "2", "language_code": "en-US", "source_api": "places_new"}, {"types": ["sublocality_level_4", "sublocality", "political"], "long_text": "2sunhwan-ro 742beon-gil", "short_text": "2sunhwan-ro 742beon-gil", "language_code": "en", "source_api": "places_new"}, {"types": ["sublocality_level_1", "sublocality", "political"], "long_text": "Heungdeok-gu", "short_text": "Heungdeok-gu", "language_code": "en", "source_api": "places_new"}, {"types": ["locality", "political"], "long_text": "Cheongju", "short_text": "Cheongju", "language_code": "ko-Latn", "source_api": "places_new"}, {"types": ["administrative_area_level_1", "political"], "long_text": "Chungcheongbuk-do", "short_text": "Chungcheongbuk-do", "language_code": "en", "source_api": "places_new"}, {"types": ["country", "political"], "long_text": "South Korea", "short_text": "KR", "language_code": "en", "source_api": "places_new"}, {"types": ["postal_code"], "long_text": "28294", "short_text": "28294", "language_code": "en-US", "source_api": "places_new"}]
A20: Dinnoteck Co.,Ltd. | B20: KR:한국 | C20: 17:Korea(General) | D20: 9F | E20: Dinnoteck | G20: 실패 | H20: FAILED_ALL_METHODS | I20: 좌표 자원이 없는 상태에서 지오코딩·TextSearch 모두 실패 | M20: https://www.google.com/maps/search/?api=1&query=Dinnoteck%20Co.%2CLtd.%209F
A21: SHINHAN DIAMOND(XI'AN) CO.,LTD. | B21: CN:중국 | C21: 250:Shaanxi | D21: 4R26+H2 중국 Shaanxi, 시안 시 창안 구 | E21: SHINHAN DIAMOND(XI'AN) | F21: 4R26+H2 Chang'An, Xi'An, Shaanxi, China | G21: 확인 필요 | H21: UNVERIFIED_NOT_FOUND | I21: 지오코딩은 성공했으나 TextSearch(좌표·주소텍스트)에서 업체 미발견 | J21: 34.101438 | K21: 108.810063 | M21: https://www.google.com/maps/search/?api=1&query=SHINHAN%20DIAMOND%28XI%27AN%29%20CO.%2CLTD.%204R26%2BH2%20%EC%A4%91%EA%B5%AD%20Shaanxi%2C%20%EC%8B%9C%EC%95%88%20%EC%8B%9C%20%EC%B0%BD%EC%95%88%20%EA%B5%AC | O21: [{"types": ["plus_code"], "long_text": "4R26+H2", "short_text": "4R26+H2", "language_code": null, "source_api": "geocoding"}, {"types": ["political", "sublocality", "sublocality_level_1"], "long_text": "Chang'An", "short_text": "Chang'An", "language_code": null, "source_api": "geocoding"}, {"types": ["locality", "political"], "long_text": "Xi'An", "short_text": "Xi'An", "language_code": null, "source_api": "geocoding"}, {"types": ["administrative_area_level_1", "political"], "long_text": "Shaanxi", "short_text": "Shaanxi", "language_code": null, "source_api": "geocoding"}, {"types": ["country", "political"], "long_text": "China", "short_text": "CN", "language_code": null, "source_api": "geocoding"}]
A22: SUZHOU POSTEL CO.,LTD | B22: CN:중국 | C22: 100:Jiangsu | D22: 工业园区利达路4号 江苏省苏州市 | E22: SUZHOU POSTEL | F22: 4 Li Da Lu, Wu Zhong Qu, Su Zhou Shi, Jiang Su Sheng, China, 215121 | G22: 확인 필요 | H22: UNVERIFIED_NOT_FOUND | I22: 지오코딩은 성공했으나 TextSearch(좌표·주소텍스트)에서 업체 미발견 | J22: 31.355620 | K22: 120.749700 | M22: https://www.google.com/maps/search/?api=1&query=SUZHOU%20POSTEL%20CO.%2CLTD%20%E5%B7%A5%E4%B8%9A%E5%9B%AD%E5%8C%BA%E5%88%A9%E8%BE%BE%E8%B7%AF4%E5%8F%B7%20%20%20%20%20%E6%B1%9F%E8%8B%8F%E7%9C%81%E8%8B%8F%E5%B7%9E%E5%B8%82 | O22: [{"types": ["street_number"], "long_text": "4", "short_text": "4", "language_code": null, "source_api": "geocoding"}, {"types": ["route"], "long_text": "Li Da Lu", "short_text": "Li Da Lu", "language_code": null, "source_api": "geocoding"}, {"types": ["political", "sublocality", "sublocality_level_1"], "long_text": "Wu Zhong Qu", "short_text": "Wu Zhong Qu", "language_code": null, "source_api": "geocoding"}, {"types": ["locality", "political"], "long_text": "Su Zhou Shi", "short_text": "Su Zhou Shi", "language_code": null, "source_api": "geocoding"}, {"types": ["administrative_area_level_1", "political"], "long_text": "Jiang Su Sheng", "short_text": "Jiang Su Sheng", "language_code": null, "source_api": "geocoding"}, {"types": ["country", "political"], "long_text": "China", "short_text": "CN", "language_code": null, "source_api": "geocoding"}, {"types": ["postal_code"], "long_text": "215121", "short_text": "215121", "language_code": null, "source_api": "geocoding"}]
A23: BOYD KOREA LLC | B23: KR:한국 | C23: 04:Chungcheongbuk-do | D23: (Hwagye-dong)2, 2Sunhwan-ro 742beon-gil, Heungdeok-gu, Cheongju-si, Chungcheongbuk-do | E23: BOYD KOREA | F23: 2 2sunhwan-ro 742beon-gil, Heungdeok-gu, Cheongju, Chungcheongbuk-do, South Korea | G23: 검증 완료 | H23: VERIFIED_GEOCODE_DIRECT | I23: 지오코딩 성공, 표준좌표 기준 TextSearch 매칭 | J23: 36.656145 | K23: 127.443492 | L23: ChIJFWasIsgpZTURvxEVwC2zlWk | M23: https://www.google.com/maps/place/?q=place_id:ChIJFWasIsgpZTURvxEVwC2zlWk | O23: [{"types": ["premise"], "long_text": "2", "short_text": "2", "language_code": "en-US", "source_api": "places_new"}, {"types": ["sublocality_level_4", "sublocality", "political"], "long_text": "2sunhwan-ro 742beon-gil", "short_text": "2sunhwan-ro 742beon-gil", "language_code": "en", "source_api": "places_new"}, {"types": ["sublocality_level_1", "sublocality", "political"], "long_text": "Heungdeok-gu", "short_text": "Heungdeok-gu", "language_code": "en", "source_api": "places_new"}, {"types": ["locality", "political"], "long_text": "Cheongju", "short_text": "Cheongju", "language_code": "ko-Latn", "source_api": "places_new"}, {"types": ["administrative_area_level_1", "political"], "long_text": "Chungcheongbuk-do", "short_text": "Chungcheongbuk-do", "language_code": "en", "source_api": "places_new"}, {"types": ["country", "political"], "long_text": "South Korea", "short_text": "KR", "language_code": "en", "source_api": "places_new"}, {"types": ["postal_code"], "long_text": "28294", "short_text": "28294", "language_code": "en-US", "source_api": "places_new"}]
A24: LT Metal Co,.LTd. | B24: KR:한국 | C24: 06:Incheon | D24: (Gajwa-dong) 14, Gajaeul-ro, Seohae-gu, Incheon, Korea | E24: LT Metal Co | F24: South Korea, Incheon, Seo-gu, 가좌3동 548-1 | G24: 검증 완료 | H24: VERIFIED_GEOCODE_PROXIMITY | I24: 지오코딩 성공, 표준좌표 기준 TextSearch 매칭(정밀좌표 근접 POI 수용: 업체명 표기 상이) | J24: 37.481420 | K24: 126.675683 | L24: ChIJuX97ykp5ezURvoBAfyo8OvE | M24: https://www.google.com/maps/place/?q=place_id:ChIJuX97ykp5ezURvoBAfyo8OvE | O24: [{"types": ["premise"], "long_text": "548-1", "short_text": "548-1", "language_code": "en-US", "source_api": "places_new"}, {"types": ["sublocality_level_2", "sublocality", "political"], "long_text": "가좌3동", "short_text": "가좌3동", "language_code": "ko", "source_api": "places_new"}, {"types": ["sublocality_level_1", "sublocality", "political"], "long_text": "Seo-gu", "short_text": "Seo-gu", "language_code": "en", "source_api": "places_new"}, {"types": ["administrative_area_level_1", "political"], "long_text": "Incheon", "short_text": "Incheon", "language_code": "en", "source_api": "places_new"}, {"types": ["country", "political"], "long_text": "South Korea", "short_text": "KR", "language_code": "en", "source_api": "places_new"}, {"types": ["postal_code"], "long_text": "22828", "short_text": "22828", "language_code": "en-US", "source_api": "places_new"}]
A25: 达成包装制品(苏州)有限公司 | B25: CN:중국 | C25: 100:Jiangsu | D25: 相城区望亭镇问渡路88号 苏州 215155 CN | E25: 达成包装制品(苏州) | F25: 88 Wen Du Lu, Xiang Cheng Qu, Su Zhou Shi, Jiang Su Sheng, China, 215155 | G25: 검증 완료 | H25: VERIFIED_GEOCODE_PROXIMITY | I25: 지오코딩 성공, 표준좌표 기준 TextSearch 매칭(정밀좌표 근접 POI 수용: 업체명 표기 상이) | J25: 31.422170 | K25: 120.442620 | L25: ChIJyUh-z12ZszURvqkpBlxLceE | M25: https://www.google.com/maps/place/?q=place_id:ChIJyUh-z12ZszURvqkpBlxLceE | O25: [{"types": ["street_number"], "long_text": "88", "short_text": "88", "language_code": "en-US", "source_api": "places_new"}, {"types": ["route"], "long_text": "Wen Du Lu", "short_text": "Wen Du Lu", "language_code": "zh-Latn", "source_api": "places_new"}, {"types": ["sublocality_level_1", "sublocality", "political"], "long_text": "Xiang Cheng Qu", "short_text": "Xiang Cheng Qu", "language_code": "zh-Latn", "source_api": "places_new"}, {"types": ["locality", "political"], "long_text": "Su Zhou Shi", "short_text": "Su Zhou Shi", "language_code": "zh-Latn", "source_api": "places_new"}, {"types": ["administrative_area_level_1", "political"], "long_text": "Jiang Su Sheng", "short_text": "Jiang Su Sheng", "language_code": "zh-Latn", "source_api": "places_new"}, {"types": ["country", "political"], "long_text": "China", "short_text": "CN", "language_code": "en", "source_api": "places_new"}, {"types": ["postal_code"], "long_text": "215155", "short_text": "215155", "language_code": "en-US", "source_api": "places_new"}]

Sheet TF_std_2
A1: TF_std | B1: 업체명 (Eng) | C1: 국가/지역 | D1: 행정구역 | E1: 주소 | F1: 위도 | G1: 경도 | H1: STD_업체명_OLD | I1: STD_주소_OLD | J1: 표준화_OLD | K1: 분류 코드_OLD | L1: 비고_OLD | M1: 참조 URL | N1: STD 업체명 | O1: STD 주소 | P1: 표준화 | Q1: 분류 코드 | R1: 비고 | S1: 표준 위도 | T1: 표준 경도 | U1: place_id | V1: 참조 URL | W1: addressComponents | X1: Comments
A2: =COUNTIF(TF_std!$A$2:$A$25, B2)>0 -> FALSE | B2: AUTO SENSOR KOREA | C2: KR:한국 | D2: 09:Gyeonggi-do | E2: 경기도 수원시 영통구 중부대로448번길 97 | F2: 37.2664485 | G2: 127.0594727 | N2: AUTO SENSOR KOREA | O2: South Korea, Gyeonggi-do, Suwon, Yeongtong-gu, 원천동 471 | P2: 검증 완료 | Q2: VERIFIED_GEOCODE_PROXIMITY | R2: 표준·기존 좌표 정합, 표준좌표 TextSearch 매칭(정밀좌표 근접 POI 수용: 업체명 표기 상이) | S2: 37.266449 | T2: 127.059473 | U2: ChIJAxmMAv5CezURpfyPu_dSeXU | V2: https://www.google.com/maps/place/?q=place_id:ChIJAxmMAv5CezURpfyPu_dSeXU | W2: [{"types": ["premise"], "long_text": "471", "short_text": "471", "language_code": "en-US", "source_api": "places_new"}, {"types": ["sublocality_level_2", "sublocality", "political"], "long_text": "원천동", "short_text": "원천동", "language_code": "ko", "source_api": "places_new"}, {"types": ["sublocality_level_1", "sublocality", "political"], "long_text": "Yeongtong-gu", "short_text": "Yeongtong-gu", "language_code": "en", "source_api": "places_new"}, {"types": ["locality", "political"], "long_text": "Suwon", "short_text": "Suwon", "language_code": "ko-Latn", "source_api": "places_new"}, {"types": ["administrative_area_level_1", "political"], "long_text": "Gyeonggi-do", "short_text": "Gyeonggi-do", "language_code": "en", "source_api": "places_new"}, {"types": ["country", "political"], "long_text": "South Korea", "short_text": "KR", "language_code": "en", "source_api": "places_new"}, {"types": ["postal_code"], "long_text": "16521", "short_text": "16521", "language_code": "en-US", "source_api": "places_new"}] | Z2: Google API 호출용 국가매핑 테이블
A3: =COUNTIF(TF_std!$A$2:$A$25, B3)>0 -> FALSE | B3: HANA TECH | C3: KR:한국 | D3: 13:Seoul | E3: 서울특별시 서초구 양재동 302-3 | F3: 37.4743262 | G3: 127.04531 | N3: HANA TECH | O3: 302-3 Yangjae-dong, Seocho District, Seoul, South Korea | P3: 확인 필요 | Q3: UNVERIFIED_NOT_FOUND | R3: 표준·기존 좌표는 정합하나 TextSearch에서 업체 미발견 | S3: 37.474326 | T3: 127.045310 | V3: - 표준: https://www.google.com/maps/search/?api=1&query=HANA%20TECH%20302-3%20Yangjae-dong%2C%20Seocho%20District%2C%20Seoul%2C%20South%20Korea - 기존: https://www.google.com/maps/search/?api=1&query=HANA%20TECH%20%EC%84%9C%EC%9A%B8%ED%8A%B9%EB%B3%84%EC%8B%9C%20%EC%84%9C%EC%B4%88%EA%B5%AC%20%EC%96%91%EC%9E%AC%EB%8F%99%20302-3 | W3: [{"types": ["premise"], "long_text": "302-3", "short_text": "302-3", "language_code": null, "source_api": "geocoding"}, {"types": ["political", "sublocality", "sublocality_level_2"], "long_text": "Yangjae-dong", "short_text": "Yangjae-dong", "language_code": null, "source_api": "geocoding"}, {"types": ["political", "sublocality", "sublocality_level_1"], "long_text": "Seocho District", "short_text": "Seocho District", "language_code": null, "source_api": "geocoding"}, {"types": ["administrative_area_level_1", "political"], "long_text": "Seoul", "short_text": "Seoul", "language_code": null, "source_api": "geocoding"}, {"types": ["country", "political"], "long_text": "South Korea", "short_text": "KR", "language_code": null, "source_api": "geocoding"}, {"types": ["postal_code"], "long_text": "06781", "short_text": "06781", "language_code": null, "source_api": "geocoding"}] | X3: 주소가 잘못된 것으로 보임. 확인 필요 판정이 정상. 표준/기존 정보 기반 URL 모두 제공. | Z3: CN: zh | AA3: 중국
A4: =COUNTIF(TF_std!$A$2:$A$25, B4)>0 -> TRUE | B4: Suzhou Kematek, Inc. | C4: CN:중국 | D4: 100:Jiangsu | E4: 1 San Qian Road Suzhou Gaoxin District | F4: 31.4 | G4: 120.17 | H4: Suzhou Kematek | I4: China, Su Zhou Shi, Hu Qiu Qu, CN 江苏省 苏州市 虎丘区 漓江路 58 58号苏州科技城工业坊B区6栋 邮政编码: 215163 | J4: 검증 완료 | K4: VERIFIED_GEOCODE_DIRECT | L4: 지오코딩 성공, 표준좌표 기준 TextSearch 매칭(G 도시레벨→TS 좌표 채택) | M4: https://www.google.com/maps/place/?q=place_id:ChIJmegxpsmdszURxrpKRCsOcA8 | N4: Suzhou Kematek | O4: China, Su Zhou Shi, Hu Qiu Qu, CN 江苏省 苏州市 虎丘区 漓江路 58 58号苏州科技城工业坊B区6栋 邮政编码: 215163 | P4: 검증 완료 | Q4: VERIFIED_COORD_DIRECT | R4: 지오코딩이 도시레벨(부정확)이라 위치비교 생략, 기존좌표 TextSearch 매칭 | S4: 31.362200 | T4: 120.415390 | U4: ChIJmegxpsmdszURxrpKRCsOcA8 | V4: https://www.google.com/maps/place/?q=place_id:ChIJmegxpsmdszURxrpKRCsOcA8 | W4: [{"types": [], "long_text": "CN 江苏省 苏州市 虎丘区 漓江路 58 58号苏州科技城工业坊B区6栋", "short_text": "", "language_code": "zh", "source_api": "places_new"}, {"types": ["country", "political"], "long_text": "China", "short_text": "CN", "language_code": "en", "source_api": "places_new"}, {"types": ["sublocality_level_1", "sublocality", "political"], "long_text": "Hu Qiu Qu", "short_text": "Hu Qiu Qu", "language_code": "zh-Latn", "source_api": "places_new"}, {"types": ["locality", "political"], "long_text": "Su Zhou Shi", "short_text": "Su Zhou Shi", "language_code": "zh-Latn", "source_api": "places_new"}, {"types": ["postal_code"], "long_text": "215163", "short_text": "215163", "language_code": "en-US", "source_api": "places_new"}] | Z4: KR: ko | AA4: 한국
A5: =COUNTIF(TF_std!$A$2:$A$25, B5)>0 -> FALSE | B5: APO(INDIUM CORPORATION OF AMERICA) | C5: SG:싱가포르 | D5: 99:Singapore (General) | E5: Unnamed Road, Singapore, Singapore | F5: 1.26332535748932 | G5: 103.875732421875 | N5: APO(INDIUM ORATION OF AMERICA) | O5: Singapore | P5: 확인 필요 | Q5: UNVERIFIED_NOT_FOUND | R5: 표준·기존 좌표 모두 TextSearch에서 업체 미발견 | S5: 1.352083 | T5: 103.819836 | V5: - 표준: https://www.google.com/maps/search/?api=1&query=APO%28INDIUM%20CORPORATION%20OF%20AMERICA%29%20Singapore - 기존: https://www.google.com/maps/search/?api=1&query=APO%28INDIUM%20CORPORATION%20OF%20AMERICA%29%20Unnamed%20Road%2C%20Singapore%2C%20Singapore | W5: [{"types": ["country", "political"], "long_text": "Singapore", "short_text": "SG", "language_code": null, "source_api": "geocoding"}] | X5: URL을 통해 구글맵 업체 검색 결과라도 사용자에게 제공. 표준/기존 정보 기반 URL 모두 제공. | Z5: VN: vi
A6: =COUNTIF(TF_std!$A$2:$A$25, B6)>0 -> FALSE | B6: Samutsakorn | C6: TH:태국 | D6: 58:Samut Sakhon | E6: ถนน ศรีสุริฉัน, Tambon Khok Kham, Amphoe Mueang Samut Sakhon, Chang Wat Samut Sakhon, Thailand, 74000 | F6: 13.5758798065832 | G6: 100.333531977028 | N6: Samutsakorn | O6: ถนน ศรีสุริฉัน Tambon Khok Kham, Amphoe Mueang Samut Sakhon, Chang Wat Samut Sakhon 74000, Thailand | P6: 확인 필요 | Q6: UNVERIFIED_NOT_FOUND | R6: 표준·기존 좌표 모두 TextSearch에서 업체 미발견 | S6: 13.575960 | T6: 100.336368 | V6: - 표준: https://www.google.com/maps/search/?api=1&query=Samutsakorn%20%E0%B8%96%E0%B8%99%E0%B8%99%20%E0%B8%A8%E0%B8%A3%E0%B8%B5%E0%B8%AA%E0%B8%B8%E0%B8%A3%E0%B8%B4%E0%B8%89%E0%B8%B1%E0%B8%99%20Tambon%20Khok%20Kham%2C%20Amphoe%20Mueang%20Samut%20Sakhon%2C%20Chang%20Wat%20Samut%20Sakhon%2074000%2C%20Thailand - 기존: https://www.google.com/maps/search/?api=1&query=Samutsakorn%20%E0%B8%96%E0%B8%99%E0%B8%99%20%E0%B8%A8%E0%B8%A3%E0%B8%B5%E0%B8%AA%E0%B8%B8%E0%B8%A3%E0%B8%B4%E0%B8%89%E0%B8%B1%E0%B8%99%2C%20Tambon%20Khok%20Kham%2C%20Amphoe%20Mueang%20Samut%20Sakhon%2C%20Chang%20Wat%20Samut%20Sakhon%2C%20Thailand%2C%2074000 | W6: [{"types": ["route"], "long_text": "ถนน ศรีสุริฉัน", "short_text": "ถนน ศรีสุริฉัน", "language_code": null, "source_api": "geocoding"}, {"types": ["locality", "political"], "long_text": "Tambon Khok Kham", "short_text": "ต.โคกขาม", "language_code": null, "source_api": "geocoding"}, {"types": ["administrative_area_level_2", "political"], "long_text": "Amphoe Mueang Samut Sakhon", "short_text": "อ. เมือง สมุทรสาคร", "language_code": null, "source_api": "geocoding"}, {"types": ["administrative_area_level_1", "political"], "long_text": "Chang Wat Samut Sakhon", "short_text": "จ.สมุทรสาคร", "language_code": null, "source_api": "geocoding"}, {"types": ["country", "political"], "long_text": "Thailand", "short_text": "TH", "language_code": null, "source_api": "geocoding"}, {"types": ["postal_code"], "long_text": "74000", "short_text": "74000", "language_code": null, "source_api": "geocoding"}] | X6: 업체명이 아닌 주(State) 이름이라 구글맵 업체 검색 결과 제공 실패. 트레이드오프: 업체명 검색 결과 URL vs. 좌표 검색 결과 URL (6행) 보통 주소가 잘못된 경우 좌표도 비정상적인 경우가 대부분이므로, 업체명(+주소) 검색 결과 URL을 제공하는 것이 나아보임. | Z6: TH: th | AA6: 태국
A7: =COUNTIF(TF_std!$A$2:$A$25, B7)>0 -> FALSE | B7: Mattson Technology | C7: CN:중국 | D7: 010:Beijing | E7: Jing Hai Qu, Tian Jin Shi, China, 301609 | F7: 38.94858178451374 | G7: 116.974683552156 | N7: Mattson Technology | O7: 47131 Bayside Pkwy, Fremont, CA 94538, USA | P7: 검증 완료 | Q7: VERIFIED_COORD_DIRECT | R7: 지오코딩이 도시레벨(부정확)이라 위치비교 생략, 기존좌표 TextSearch 매칭 | S7: 37.475363 | T7: -121.937337 | U7: ChIJB3kfDDfGj4ARv8RvYZKoPVg | V7: https://www.google.com/maps/place/?q=place_id:ChIJB3kfDDfGj4ARv8RvYZKoPVg | W7: [{"types": ["street_number"], "long_text": "47131", "short_text": "47131", "language_code": "en-US", "source_api": "places_new"}, {"types": ["route"], "long_text": "Bayside Parkway", "short_text": "Bayside Pkwy", "language_code": "en", "source_api": "places_new"}, {"types": ["neighborhood", "political"], "long_text": "Baylands", "short_text": "Baylands", "language_code": "en", "source_api": "places_new"}, {"types": ["locality", "political"], "long_text": "Fremont", "short_text": "Fremont", "language_code": "en", "source_api": "places_new"}, {"types": ["administrative_area_level_2", "political"], "long_text": "Alameda County", "short_text": "Alameda County", "language_code": "en", "source_api": "places_new"}, {"types": ["administrative_area_level_1", "political"], "long_text": "California", "short_text": "CA", "language_code": "en", "source_api": "places_new"}, {"types": ["country", "political"], "long_text": "United States", "short_text": "US", "language_code": "en", "source_api": "places_new"}, {"types": ["postal_code"], "long_text": "94538", "short_text": "94538", "language_code": "en-US", "source_api": "places_new"}, {"types": ["postal_code_suffix"], "long_text": "6517", "short_text": "6517", "language_code": "en-US", "source_api": "places_new"}] | Z7: MY: ms | AA7: 말레이시아
A8: =COUNTIF(TF_std!$A$2:$A$25, B8)>0 -> FALSE | B8: Gu Xuan | C8: CN:중국 | D8: 250:Shaanxi | F8: 34.430609 | G8: 108.806889 | N8: Gu Xuan | O8: 7RVP+4JH, Xi An Gao Jia Kuai Su Gan Dao, Wei Yang Qu, Xi An Shi, Shan Xi Sheng, China, 710086 | P8: 검증 완료 | Q8: VERIFIED_COORD_DIRECT | R8: 기존좌표 기준 TextSearch 매칭 | S8: 34.292820 | T8: 108.836599 | U8: ChIJ-UHemVx4YzYRZJii3fXq4B0 | V8: https://www.google.com/maps/place/?q=place_id:ChIJ-UHemVx4YzYRZJii3fXq4B0 | W8: [{"types": ["plus_code"], "long_text": "7RVP+4JH", "short_text": "7RVP+4JH", "language_code": "en-US", "source_api": "places_new"}, {"types": ["route"], "long_text": "Xi An Gao Jia Kuai Su Gan Dao", "short_text": "Xi An Gao Jia Kuai Su Gan Dao", "language_code": "zh-Latn", "source_api": "places_new"}, {"types": ["sublocality_level_1", "sublocality", "political"], "long_text": "Wei Yang Qu", "short_text": "Wei Yang Qu", "language_code": "zh-Latn", "source_api": "places_new"}, {"types": ["locality", "political"], "long_text": "Xi An Shi", "short_text": "Xi An Shi", "language_code": "zh-Latn", "source_api": "places_new"}, {"types": ["administrative_area_level_1", "political"], "long_text": "Shan Xi Sheng", "short_text": "Shan Xi Sheng", "language_code": "zh-Latn", "source_api": "places_new"}, {"types": ["country", "political"], "long_text": "China", "short_text": "CN", "language_code": "en", "source_api": "places_new"}, {"types": ["postal_code"], "long_text": "710086", "short_text": "710086", "language_code": "en-US", "source_api": "places_new"}] | Z8: MX: es | AA8: 멕시코
A9: =COUNTIF(TF_std!$A$2:$A$25, B9)>0 -> TRUE | B9: Honeywell Automation and Control Solution(China) Co.,Ltd. | C9: CN:중국 | D9: 020:Shanghai | E9: FUTE NORTH ROAD NO.456 5F A2 ROOM SHANGHAI PILOT FREE TRADE ZONE | F9: 31.089126813768 | G9: 121.940074704927 | H9: Honeywell Automation and Control Solution(China) | I9: Shanghai, China | J9: 확인 필요 | K9: UNVERIFIED_NOT_FOUND | L9: 지오코딩은 성공했으나 TextSearch(좌표·주소텍스트)에서 업체 미발견 | M9: https://www.google.com/maps/search/?api=1&query=Honeywell%20Automation%20and%20Control%20Solution%28China%29%20Co.%2CLtd.%20FUTE%20NORTH%20ROAD%20NO.456%205F%20A2%20ROOM%20SHANGHAI%20PILOT%20FREE%20TRADE%20ZONE | N9: Honeywell Automation and Control Solution(China) | O9: Shanghai, China | P9: 확인 필요 | Q9: UNVERIFIED_NOT_FOUND | R9: 표준·기존 좌표 모두 TextSearch에서 업체 미발견 | S9: 31.230416 | T9: 121.473701 | V9: - 표준: https://www.google.com/maps/search/?api=1&query=Honeywell%20Automation%20and%20Control%20Solution%28China%29%20Co.%2CLtd.%20Shanghai%2C%20China - 기존: https://www.google.com/maps/search/?api=1&query=Honeywell%20Automation%20and%20Control%20Solution%28China%29%20Co.%2CLtd.%20FUTE%20NORTH%20ROAD%20NO.456%205F%20A2%20ROOM%20SHANGHAI%20PILOT%20FREE%20TRADE%20ZONE | W9: [{"types": ["locality", "political"], "long_text": "Shanghai", "short_text": "Shanghai", "language_code": null, "source_api": "geocoding"}, {"types": ["administrative_area_level_1", "political"], "long_text": "Shanghai", "short_text": "Shanghai", "language_code": null, "source_api": "geocoding"}, {"types": ["country", "political"], "long_text": "China", "short_text": "CN", "language_code": null, "source_api": "geocoding"}] | X9: 트레이드오프: 업체명 검색 결과 URL vs. 좌표 검색 결과 URL (6행) 보통 주소가 잘못된 경우 좌표도 비정상적인 경우가 대부분이므로, 업체명(+주소) 검색 결과 URL을 제공하는 것이 나아보임. | Z9: JP: ja | AA9: 일본
A10: =COUNTIF(TF_std!$A$2:$A$25, B10)>0 -> TRUE | B10: CINOS(CX1,CX2) | C10: CN:중국 | D10: 250:Shaanxi | E10: 중국 Shan Xi Sheng, Xi An Shi, Ba Qiao Qu, 亚洲道93WF+8X9 邮政编码: 710027 | F10: 34.395799 | G10: 109.074973 | H10: CINOS(CX1,CX2) | I10: China, Shan Xi Sheng, Xi An Shi, Ba Qiao Qu, 亚洲道93WG+FFR 邮政编码: 710027 | J10: 확인 필요 | K10: UNVERIFIED_NOT_FOUND | L10: 지오코딩은 성공했으나 TextSearch(좌표·주소텍스트)에서 업체 미발견 | M10: https://www.google.com/maps/search/?api=1&query=CINOS%28CX1%2CCX2%29%20%EC%A4%91%EA%B5%AD%20Shan%20Xi%20Sheng%2C%20Xi%20An%20Shi%2C%20Ba%20Qiao%20Qu%2C%20%E4%BA%9A%E6%B4%B2%E9%81%9393WF%2B8X9%20%E9%82%AE%E6%94%BF%E7%BC%96%E7%A0%81%3A%20710027 | N10: CINOS(CX1,CX2) | O10: China, Shan Xi Sheng, Xi An Shi, Ba Qiao Qu, 亚洲道93WG+FFR 邮政编码: 710027 | P10: 확인 필요 | Q10: UNVERIFIED_NOT_FOUND | R10: 표준·기존 좌표 모두 TextSearch에서 업체 미발견 | S10: 34.396238 | T10: 109.076148 | V10: - 표준: https://www.google.com/maps/search/?api=1&query=CINOS%28CX1%2CCX2%29%20China%2C%20Shan%20Xi%20Sheng%2C%20Xi%20An%20Shi%2C%20Ba%20Qiao%20Qu%2C%20%E4%BA%9A%E6%B4%B2%E9%81%9393WG%2BFFR%20%E9%82%AE%E6%94%BF%E7%BC%96%E7%A0%81%3A%20710027 - 기존: https://www.google.com/maps/search/?api=1&query=CINOS%28CX1%2CCX2%29%20%EC%A4%91%EA%B5%AD%20Shan%20Xi%20Sheng%2C%20Xi%20An%20Shi%2C%20Ba%20Qiao%20Qu%2C%20%E4%BA%9A%E6%B4%B2%E9%81%9393WF%2B8X9%20%E9%82%AE%E6%94%BF%E7%BC%96%E7%A0%81%3A%20710027 | W10: [{"types": ["plus_code"], "long_text": "93WG+FFR", "short_text": "93WG+FFR", "language_code": null, "source_api": "geocoding"}, {"types": ["route"], "long_text": "亚洲道", "short_text": "亚洲道", "language_code": null, "source_api": "geocoding"}, {"types": ["political", "sublocality", "sublocality_level_1"], "long_text": "Ba Qiao Qu", "short_text": "Ba Qiao Qu", "language_code": null, "source_api": "geocoding"}, {"types": ["locality", "political"], "long_text": "Xi An Shi", "short_text": "Xi An Shi", "language_code": null, "source_api": "geocoding"}, {"types": ["administrative_area_level_1", "political"], "long_text": "Shan Xi Sheng", "short_text": "Shan Xi Sheng", "language_code": null, "source_api": "geocoding"}, {"types": ["country", "political"], "long_text": "China", "short_text": "CN", "language_code": null, "source_api": "geocoding"}, {"types": ["postal_code"], "long_text": "710027", "short_text": "710027", "language_code": null, "source_api": "geocoding"}] | X10: 트레이드오프: 업체명 검색 결과 URL vs. 좌표 검색 결과 URL (6행) 보통 주소가 잘못된 경우 좌표도 비정상적인 경우가 대부분이므로, 업체명(+주소) 검색 결과 URL을 제공하는 것이 나아보임. | Z10: TW: zh-TW | AA10: 대만
A11: =COUNTIF(TF_std!$A$2:$A$25, B11)>0 -> FALSE | B11: 제일써보테크 | C11: KR:한국 | D11: 09:Gyeonggi-do | E11: 경기도 부천시 도당동 255-1 | F11: 37.5091393 | G11: 126.7846143 | N11: 제일써보테크 | O11: 255-1 Dodang-dong, Bucheon, Gyeonggi-do, South Korea | P11: 확인 필요 | Q11: UNVERIFIED_NOT_FOUND | R11: 표준·기존 좌표는 정합하나 TextSearch에서 업체 미발견 | S11: 37.509139 | T11: 126.784614 | V11: - 표준: https://www.google.com/maps/search/?api=1&query=%EC%A0%9C%EC%9D%BC%EC%8D%A8%EB%B3%B4%ED%85%8C%ED%81%AC%20255-1%20Dodang-dong%2C%20Bucheon%2C%20Gyeonggi-do%2C%20South%20Korea - 기존: https://www.google.com/maps/search/?api=1&query=%EC%A0%9C%EC%9D%BC%EC%8D%A8%EB%B3%B4%ED%85%8C%ED%81%AC%20%EA%B2%BD%EA%B8%B0%EB%8F%84%20%EB%B6%80%EC%B2%9C%EC%8B%9C%20%EB%8F%84%EB%8B%B9%EB%8F%99%20255-1 | W11: [{"types": ["premise"], "long_text": "255-1", "short_text": "255-1", "language_code": null, "source_api": "geocoding"}, {"types": ["political", "sublocality", "sublocality_level_2"], "long_text": "Dodang-dong", "short_text": "Dodang-dong", "language_code": null, "source_api": "geocoding"}, {"types": ["locality", "political"], "long_text": "Bucheon", "short_text": "Bucheon", "language_code": null, "source_api": "geocoding"}, {"types": ["administrative_area_level_1", "political"], "long_text": "Gyeonggi-do", "short_text": "Gyeonggi-do", "language_code": null, "source_api": "geocoding"}, {"types": ["country", "political"], "long_text": "South Korea", "short_text": "KR", "language_code": null, "source_api": "geocoding"}, {"types": ["postal_code"], "long_text": "14524", "short_text": "14524", "language_code": null, "source_api": "geocoding"}] | X11: 제공된 주소 및 좌표 근처에서 업체 식별되지 않았으나, URL을 통해 부천 시 내 존재하는 동명 업체 정보 제공. | Z11: HK: zh-HK | AA11: 홍콩
A12: =COUNTIF(TF_std!$A$2:$A$25, B12)>0 -> FALSE | B12: EHWA DiamEHWA Diamond Industrial Co., Ltd. | C12: KR:한국 | D12: 09:Gyeonggi-do | E12: 대한민국 경기도 화성시 방교동 801 | F12: 37.165313662862 | G12: 127.083885829268 | N12: EHWA DiamEHWA Diamond Industrial | O12: 801 Banggyo-dong, Hwaseong-si, Gyeonggi-do, South Korea | P12: 확인 필요 | Q12: UNVERIFIED_PLACEID_MISMATCH | R12: 표준·기존 좌표에서 서로 다른 업체 발견 → 동명이업체/위치오류 의심(두 후보 제시) | S12: 37.165757 | T12: 127.084305 | V12: https://www.google.com/maps/place/?q=place_id:ChIJVVVVVV5GezUR15dJk1XRDQw | W12: [{"types": ["premise"], "long_text": "801", "short_text": "801", "language_code": null, "source_api": "geocoding"}, {"types": ["political", "sublocality", "sublocality_level_2"], "long_text": "Banggyo-dong", "short_text": "Banggyo-dong", "language_code": null, "source_api": "geocoding"}, {"types": ["locality", "political"], "long_text": "Hwaseong-si", "short_text": "Hwaseong-si", "language_code": null, "source_api": "geocoding"}, {"types": ["administrative_area_level_1", "political"], "long_text": "Gyeonggi-do", "short_text": "Gyeonggi-do", "language_code": null, "source_api": "geocoding"}, {"types": ["country", "political"], "long_text": "South Korea", "short_text": "KR", "language_code": null, "source_api": "geocoding"}, {"types": ["postal_code"], "long_text": "18487", "short_text": "18487", "language_code": null, "source_api": "geocoding"}, {"types": ["premise"], "long_text": "10", "short_text": "10", "language_code": "en-US", "source_api": "places_new"}, {"types": ["sublocality_level_4", "sublocality", "political"], "long_text": "Dongtansandan 3-gil", "short_text": "Dongtansandan 3-gil", "language_code": "en", "source_api": "places_new"}, {"types": ["sublocality_level_2", "sublocality", "political"], "long_text": "동탄면", "short_text": "동탄면", "language_code": "ko", "source_api": "places_new"}, {"types": ["locality", "political"], "long_text": "Hwaseong-si", "short_text": "Hwaseong-si", "language_code": "en", "source_api": "places_new"}, {"types": ["administrative_area_level_1", "political"], "long_text": "Gyeonggi-do", "short_text": "Gyeonggi-do", "language_code": "en", "source_api": "places_new"}, {"types": ["country", "political"], "long_text": "South Korea", "short_text": "KR", "language_code": "en", "source_api": "places_new"}, {"types": ["postal_code"], "long_text": "18487", "short_text": "18487", "language_code": "en-US", "source_api": "places_new"}] | X12: 1. Geocoding 표준 결과가 존재하고, 표준좌표와 기존좌표의 거리가 먼 경우, 기존 좌표로 TextSearch 수행 2. TextSearch 결과가 존재할 때, Geocoding 표준 결과 비교하여 다르면 MISMATCH 판정 및 복수개 URL 제공하여 사용자가 택1 하였으나, 3. "1"에서 기존좌표 정보를 신뢰하고 사용자의 편의를 위해, MISMATCH 시 TextSearch URL을 제공 (분류 코드는 MISMATCH로 유지하여 추후 검증 용이성 확보). | Z12: * 매핑 실패시에만 현지어로 시도
A13: =COUNTIF(TF_std!$A$2:$A$25, B13)>0 -> TRUE | B13: Air Liquide Electronics US LP | C13: US:미합중국 | D13: US_99 | E13: PO BOX 200269 HOUSTON TX | F13: 40.1742465094527 | G13: -74.7703792317304 | H13: Air Liquide Electronics US LP | I13: 9811 Katy Fwy #100, Houston, TX 77024, USA | J13: 검증 완료 | K13: VERIFIED_GEOCODE_DIRECT | L13: 지오코딩 성공, 표준좌표 기준 TextSearch 매칭(G 도시레벨→TS 좌표 채택) | M13: https://www.google.com/maps/place/?q=place_id:ChIJsTtJC6y4QIYRSI2XSZdeW3Q | N13: Air Liquide Electronics US LP | O13: 197 Meister Ave, Branchburg, NJ 08876, USA | P13: 검증 완료 | Q13: VERIFIED_COORD_DIRECT | R13: 지오코딩이 도시레벨(부정확)이라 위치비교 생략, 기존좌표 TextSearch 매칭 | S13: 40.606052 | T13: -74.715034 | U13: ChIJwclNyROTw4kRbAlL-Y9a5H8 | V13: https://www.google.com/maps/place/?q=place_id:ChIJwclNyROTw4kRbAlL-Y9a5H8 | W13: [{"types": ["street_number"], "long_text": "197", "short_text": "197", "language_code": "en-US", "source_api": "places_new"}, {"types": ["route"], "long_text": "Meister Avenue", "short_text": "Meister Ave", "language_code": "en", "source_api": "places_new"}, {"types": ["locality", "political"], "long_text": "Branchburg", "short_text": "Branchburg", "language_code": "en", "source_api": "places_new"}, {"types": ["administrative_area_level_2", "political"], "long_text": "Somerset County", "short_text": "Somerset County", "language_code": "en", "source_api": "places_new"}, {"types": ["administrative_area_level_1", "political"], "long_text": "New Jersey", "short_text": "NJ", "language_code": "en", "source_api": "places_new"}, {"types": ["country", "political"], "long_text": "United States", "short_text": "US", "language_code": "en", "source_api": "places_new"}, {"types": ["postal_code"], "long_text": "08876", "short_text": "08876", "language_code": "en-US", "source_api": "places_new"}, {"types": ["postal_code_suffix"], "long_text": "6022", "short_text": "6022", "language_code": "en-US", "source_api": "places_new"}]
A14: =COUNTIF(TF_std!$A$2:$A$25, B14)>0 -> TRUE | B14: Entegris Malaysia Sdn Bhd | C14: MY:말레이시아 | D14: KED:Kedah | E14: CHV7+63 Lunas, Kedah, 말레이시아 | F14: 5.44304220161746 | G14: 100.562630683701 | H14: Entegris Malaysia Sdn Bhd | I14: Lot 17, Fasa 1 Kulim Hi-Tech Park, Kedah, Taman Kulim Hi-tech, 09000 Kulim, Kedah, Malaysia | J14: 검증 완료 | K14: VERIFIED_TEXTSEARCH_ADDR_TEXT | L14: 표준좌표 TextSearch 미매칭, 업체명+주소텍스트 TextSearch로 매칭(레벨 L1) | M14: https://www.google.com/maps/place/?q=place_id:ChIJq6qqqubMSjAR7P43RFFhmpU | N14: Entegris Malaysia Sdn Bhd | O14: CHV7+63 Lunas, Kedah, Malaysia | P14: 확인 필요 | Q14: UNVERIFIED_NOT_FOUND | R14: 표준·기존 좌표는 정합하나 TextSearch에서 업체 미발견 | S14: 5.443062 | T14: 100.562687 | V14: - 표준: https://www.google.com/maps/search/?api=1&query=Entegris%20Malaysia%20Sdn%20Bhd%20CHV7%2B63%20Lunas%2C%20Kedah%2C%20Malaysia - 기존: https://www.google.com/maps/search/?api=1&query=Entegris%20Malaysia%20Sdn%20Bhd%20CHV7%2B63%20Lunas%2C%20Kedah%2C%20%EB%A7%90%EB%A0%88%EC%9D%B4%EC%8B%9C%EC%95%84 | W14: [{"types": ["plus_code"], "long_text": "CHV7+63", "short_text": "CHV7+63", "language_code": null, "source_api": "geocoding"}, {"types": ["locality", "political"], "long_text": "Lunas", "short_text": "Lunas", "language_code": null, "source_api": "geocoding"}, {"types": ["administrative_area_level_1", "political"], "long_text": "Kedah", "short_text": "Kedah", "language_code": null, "source_api": "geocoding"}, {"types": ["country", "political"], "long_text": "Malaysia", "short_text": "MY", "language_code": null, "source_api": "geocoding"}] | X14: 입력된 주소의 품질에 따라 판정 차이 발생 (22행과 비교). URL을 통해 사용자가 편리하게 검증 가능하나, 충분히 "검증 완료" 받을 수 있었던 케이스. | Z14: 소계 | AA14: =ROWS(B2:B39) -> 38
A15: =COUNTIF(TF_std!$A$2:$A$25, B15)>0 -> FALSE | B15: JUHUA | C15: CN:중국 | D15: 130:Zhejiang | E15: VWX4+QP5, Kecheng District, Quzhou, Zhejiang, China, 324004 | F15: 28.8993915855368 | G15: 118.906831741333 | N15: JUHUA | O15: China, Zhe Jiang Sheng, Qu Zhou Shi, Ke Cheng Qu, 中央道VVXX+JGF 邮政编码: 324004 | P15: 검증 완료 | Q15: VERIFIED_GEOCODE_DIRECT | R15: 표준·기존 좌표 정합, 표준좌표 TextSearch 매칭 | S15: 28.899387 | T15: 118.906859 | U15: ChIJTYNXlKUxSDQRQyp-LcKW_c0 | V15: https://www.google.com/maps/place/?q=place_id:ChIJTYNXlKUxSDQRQyp-LcKW_c0 | W15: [{"types": ["plus_code"], "long_text": "VVXX+JGF", "short_text": "VVXX+JGF", "language_code": "en-US", "source_api": "places_new"}, {"types": ["route"], "long_text": "中央道", "short_text": "中央道", "language_code": "zh", "source_api": "places_new"}, {"types": ["sublocality_level_1", "sublocality", "political"], "long_text": "Ke Cheng Qu", "short_text": "Ke Cheng Qu", "language_code": "zh-Latn", "source_api": "places_new"}, {"types": ["locality", "political"], "long_text": "Qu Zhou Shi", "short_text": "Qu Zhou Shi", "language_code": "zh-Latn", "source_api": "places_new"}, {"types": ["administrative_area_level_1", "political"], "long_text": "Zhe Jiang Sheng", "short_text": "Zhe Jiang Sheng", "language_code": "zh-Latn", "source_api": "places_new"}, {"types": ["country", "political"], "long_text": "China", "short_text": "CN", "language_code": "en", "source_api": "places_new"}, {"types": ["postal_code"], "long_text": "324004", "short_text": "324004", "language_code": "en-US", "source_api": "places_new"}] | X15: 입력된 주소가 특정 범위(상세 정보 확인 불가) 내에서 세부 구역 ID까지 포함하나, 구글 표준주소로 변경되며 실제 등록된 업체의 주소로 맞춰짐. 15, 16행의 주소가 표준화되어 동일 업체임을 확인할 수 있는 좋은 케이스. | Z15: 검증 완료 | AA15: =COUNTIF(P2:P39, "검증 완료") -> 13
A16: =COUNTIF(TF_std!$A$2:$A$25, B16)>0 -> FALSE | B16: JUHUA | C16: CN:중국 | D16: 130:Zhejiang | E16: WV3J+W2, Kecheng District, Quzhou, Zhejiang, China | F16: 28.9047566017496 | G16: 118.880123498853 | N16: JUHUA | O16: China, Zhe Jiang Sheng, Qu Zhou Shi, Ke Cheng Qu, 中央道VVXX+JGF 邮政编码: 324004 | P16: 검증 완료 | Q16: VERIFIED_GEOCODE_DIRECT | R16: 표준·기존 좌표 정합, 표준좌표 TextSearch 매칭 | S16: 28.904812 | T16: 118.880062 | U16: ChIJTYNXlKUxSDQRQyp-LcKW_c0 | V16: https://www.google.com/maps/place/?q=place_id:ChIJTYNXlKUxSDQRQyp-LcKW_c0 | W16: [{"types": ["plus_code"], "long_text": "VVXX+JGF", "short_text": "VVXX+JGF", "language_code": "en-US", "source_api": "places_new"}, {"types": ["route"], "long_text": "中央道", "short_text": "中央道", "language_code": "zh", "source_api": "places_new"}, {"types": ["sublocality_level_1", "sublocality", "political"], "long_text": "Ke Cheng Qu", "short_text": "Ke Cheng Qu", "language_code": "zh-Latn", "source_api": "places_new"}, {"types": ["locality", "political"], "long_text": "Qu Zhou Shi", "short_text": "Qu Zhou Shi", "language_code": "zh-Latn", "source_api": "places_new"}, {"types": ["administrative_area_level_1", "political"], "long_text": "Zhe Jiang Sheng", "short_text": "Zhe Jiang Sheng", "language_code": "zh-Latn", "source_api": "places_new"}, {"types": ["country", "political"], "long_text": "China", "short_text": "CN", "language_code": "en", "source_api": "places_new"}, {"types": ["postal_code"], "long_text": "324004", "short_text": "324004", "language_code": "en-US", "source_api": "places_new"}] | X16: 입력된 주소가 특정 범위(상세 정보 확인 불가) 내에서 세부 구역 ID까지 포함하나, 구글 표준주소로 변경되며 실제 등록된 업체의 주소로 맞춰짐. 15, 16행의 주소가 표준화되어 동일 업체임을 확인할 수 있는 좋은 케이스. | Z16: 확인 필요 | AA16: =COUNTIF(P3:P40, "확인 필요") -> 24
